<?xml version="1.0"?>
<robot xmlns:xacro="http://www.ros.org/wiki/xacro">
    <!-- <xacro:include filename="$(find dogbot_description)/urdf/dogbot/common_inertia.xacro"/> -->
    <xacro:macro name="wheel_xacro" params="wheel_name xyz radius length">
        <link name="${wheel_name}_link">
            <visual>
                <origin xyz="0.0 0.0 0.0" rpy="1.57079 0.0 0.0"/>
                <geometry>
                    <cylinder radius="${radius}" length="${length}"/>
                </geometry>
                <material name="yellow">
                    <color rgba="1.0 1.0 0.0 1.0"/>
                </material>
            </visual>
            <collision>
                <origin xyz="0.0 0.0 0.0" rpy="1.57079 0.0 0.0"/>
                <geometry>
                    <cylinder radius="${radius}" length="${length}"/>
                </geometry>
                <material name="yellow">
                    <color rgba="1.0 1.0 0.0 1.0"/>
                </material>
            </collision>
            <!-- <xacro:cylinder_inertia m="0.05" r="${radius}" h="${length}" /> -->
        </link>

        <joint name="${wheel_name}_joint" type="continuous">
            <origin xyz="${xyz}" rpy="0.0 0.0 0.0"/>
            <parent link="base_link"/>
            <child link="${wheel_name}_link"/>
            <axis xyz="0.0 1.0 0.0"/>
        </joint>

        <!-- <gazebo reference="${wheel_name}_link">
            <material>
                Gazebo/Yellow
            </material>
            <mu1 value="20.0" />
            <mu2 value="20.0" />
            <kp value="1000000000.0" />
            <kd value="1.0" />
        </gazebo> -->
    </xacro:macro>
</robot>